Workbook

Sheet readme
A1: Финансовый анализ ПАО Сургутнефтегаз
A2: Период: 2022-2023 (РСБУ)
A3: Автор: Бабаев Эльдар eldarba18@gmail.com
A5: Содержание
A6: Лист | B6: Описание
A7: Баланс | B7: Агрегированный бухгалтерский баланс 2022/2023, абсолютная динамика (Δ) и относительная (Δ%), структура баланса
A8: ОФР | B8: Отчёт о финансовых результатах 2022/2023: выручка, себестоимость, прибыль от продаж, прочие доходы/расходы, налог, чистая прибыль
A9: Потоки | B9: Потоки денежных средств: операционная, инвестиционная, финансовая деятельность. Жизненный цикл — классическая зрелость
A10: Обор | B10: Показатели оборачиваемости: коэффициенты К1/К2, производственно-коммерческий цикл, кредитный, чистый цикл
A11: ликв | B11: Показатели ликвидности: Активы/Пассивы, коэффициенты текущей/абсолютной/среднесрочной ликвидности, коэффициент покрытия, расчёт минимально допустимого Кобл
A12: финуст | B12: Показатели финансовой устойчивости: коэффициент автономии, минимально допустимый автономии, Альтман, ОДАСС, самофинансирование, мобилизация накопленного капитала
A13: рент | B13: Рентабельность: ROE, ROA, эффект рычага. Operating ROE. Факторный анализ Дюпон (цепные подстановки)
A14: сводная | B14: Сводная таблица 25+ финансовых коэффициентов с категориями, сравнением со среднеотраслевыми и оценкой по каждому показателю
A15: эк.приб. | B15: Расчёт стоимости собственного капитала (Ke) через CAPM и экономической прибыли (EVA). Ключевой insight: ROE < Ke => бизнес разрушает стоимость
A18: Источники
A19: РСБУ 2023 | B19: Бухгалтерская отчётность ПАО Сургутнефтегаз за 2022 и 2023 годы (smart-lab.ru)
A20: Среднеотраслевые зн. | B20: testfirm.ru, сектор 06 (добыча нефти и газа), по крупным предприятиям
A21: Эк. Прибыль | B21: Damodaran
A23: Ключевые выводы
A24: 1. Ликвидность | B24: Компания абсолютно ликвидна (Кобл 5.45 при минимальном 1.14, Кмл=0.3).
A25: 2. Фин. устойчивость | B25: Коэффициент автономии 0.90 при норме 0.29 — недозагрузка финансового рычага, потенциал привлечения заёмного капитала
A26: 3. Рентабельность | B26: ROS по чистой прибыли 60% завышена прочими доходами. Операционная ROS намного меньше 12.62% - ниже средней по рынку
A27: 4. Главный риск | B27: Отрицательная эк. прибыль (-412 млрд руб): ROE (17.85%) ниже стоимости капитала Ke (23.37%) — бизнес не создаёт стоимость для акционеров
A28: 5. Рекомендации | B28: Привлечение заёмного капитала для эффекта рычага; оптимизация оборачиваемости запасов; диверсификация доходов от прочих видов деятельности

Sheet Баланс
A1: Агрегирование баланса ПАО "Сургутнефтегаз" | C1: Содержание
A2: Наименование показателя | B2: На 31 декабря 2023 года | C2: На 31 декабря 2022 года | D2: Изменение | E2: Изменение, %
A3: Актив
A4: 1. Внеоборотные активы
A5: Нематериальные активы | B5: =258991+80199+118143995 -> 118483185 | C5: 100441138 | D5: =B5-C5 -> 18042047 | E5: =D5/C5 -> 0.17962806
A6: Основные средства | B6: =1780998859-B7 -> 1683733571 | C6: 1554602062 | D6: =B6-C6 -> 129131509 | E6: =D6/C6 -> 0.083064028
A7: Незавершенные капитальные вложения | B7: 97265288 | C7: 88890783 | D7: =B7-C7 -> 8374505 | E7: =D7/C7 -> 0.094211174
A8: Долгосрочные финансовые вложения | B8: 4157418676 | C8: 2147558760 | D8: =B8-C8 -> 2009859916 | E8: =D8/C8 -> 0.93588122
A9: Прочие внеоборотные активы | B9: =68671352+48697484+85116158 -> 202484994 | C9: 144158282 | D9: =B9-C9 -> 58326712 | E9: =D9/C9 -> 0.40460188
A10: Итого по разделу 1 | B10: =SUM(B5:B9) -> 6259385714 | C10: =SUM(C5:C9) -> 4035651025 | D10: =B10-C10 -> 2223734689 | E10: =D10/C10 -> 0.55102254
A11: 2. Оборотные активы
A12: Авансы поставщикам | B12: 6483299 | C12: 6995927 | D12: =B12-C12 -> -512628 | E12: =D12/C12 -> -0.073275207
A13: Сырье и материалы | B13: =128911694*0.62 -> 79925250 | C13: 67831061 | D13: =B13-C13 -> 12094189 | E13: =D13/C13 -> 0.17829869
A14: Незавершенное производство | B14: =128911694*0.107 -> 13793551 | C14: 8801022 | D14: =B14-C14 -> 4992529.3 | E14: =D14/C14 -> 0.56726699
A15: Готовая продукция и товары | B15: =128911694*0.25 -> 32227924 | C15: 25431978 | D15: =B15-C15 -> 6795945.5 | E15: =D15/C15 -> 0.26722049
A16: Дебиторская задолженность | B16: =370070251-B12-85116158 -> 278470794 | C16: 241855930 | D16: =B16-C16 -> 36614864 | E16: =D16/C16 -> 0.15139122
A17: Денежные средства и денежные эквиваленты | B17: 117322239 | C17: 103639491 | D17: =B17-C17 -> 13682748 | E17: =D17/C17 -> 0.13202253
A18: Прочие оборотные активы | B18: =8292304+4527335+1502886150+2811094 -> 1518516883 | C18: 2186644582 | D18: =B18-C18 -> -668127699 | E18: =D18/C18 -> -0.30554929
A19: Итого по разделу 2 | B19: =SUM(B12:B18) -> 2.0467399e+09 | C19: =SUM(C12:C18) -> 2641199991 | D19: =B19-C19 -> -5.9446005e+08 | E19: =D19/C19 -> -0.22507196
A20: Баланс | B20: =B10+B19 -> 8.3061257e+09 | C20: =C10+C19 -> 6676851016 | D20: =B20-C20 -> 1.6292746e+09 | E20: =D20/C20 -> 0.24401842
A21: Пассив
A22: Собственные средства
A23: Уставный капитал | B23: =43427993+192511786+317163645 -> 553103424 | C23: 540262471 | D23: =B23-C23 -> 12840953 | E23: =D23/C23 -> 0.02376799
A24: Накопленный капитал | B24: =6514198+6913861929 -> 6920376127 | C24: 5616029413 | D24: =B24-C24 -> 1304346714 | E24: =D24/C24 -> 0.23225425
A25: Итого собственных средств | B25: =SUM(B23:B24) -> 7473479551 | C25: =SUM(C23:C24) -> 6156291884 | D25: =B25-C25 -> 1317187667 | E25: =D25/C25 -> 0.21395796
A26: Заемные средства
A27: Долгосрочные обязательства | B27: 438844622 | C27: 254061278 | D27: =B27-C27 -> 184783344 | E27: =D27/C27 -> 0.72731801
A28: Краткосрочные обязательства
A29: Краткосрочные кредиты | B29: - | C29: -
A30: Кредиторская задолженность (счета к оплате) | B30: =368881966*0.075 -> 27666147 | C30: 25064417 | D30: =B30-C30 -> 2601730.4 | E30: =D30/C30 -> 0.10380175
A31: Авансы полученные | B31: 73860933 | C31: 44466308 | D31: =B31-C31 -> 29394625 | E31: =D31/C31 -> 0.66105387
A32: Расчеты с бюджетом и внебюджетными фондами | B32: =368881966*0.623 -> 2.2981346e+08 | C32: 149277468 | D32: =B32-C32 -> 80535997 | E32: =D32/C32 -> 0.53950538
A33: Расчеты по заработной плате | B33: - | C33: -
A34: Прочие краткосрочные обязательства | B34: =24840752+6277910+6440000-17241+21836593+524983+13253+2544686 -> 62460936 | C34: =21248154+1182725+13141+25245641 -> 47689661 | D34: =B34-C34 -> 14771275 | E34: =D34/C34 -> 0.30973747
A35: Итого краткосрочных обязательств | B35: =SUM(B29:B34) -> 3.9380148e+08 | C35: =SUM(C29:C34) -> 266497854 | D35: =B35-C35 -> 1.2730363e+08 | E35: =D35/C35 -> 0.477691
A36: Итого заемных средств | B36: =B35+B27 -> 8.326461e+08 | C36: =C35+C27 -> 520559132 | D36: =B36-C36 -> 3.1208697e+08 | E36: =D36/C36 -> 0.59952261
A37: Баланс | B37: =SUM(B36,B25) -> 8.3061257e+09 | C37: =SUM(C36,C25) -> 6676851016 | D37: =B37-C37 -> 1.6292746e+09 | E37: =D37/C37 -> 0.24401842
A39: Структура баланса
A40: Наименование показателя | B40: На 31 декабря 2023 года | C40: На 31 декабря 2022 года
A41: Актив
...

Sheet ОФР
A1: Отчет о финансовых результатах | C1: Содержание
A3: Наименование показателя | B3: за 2023 | C3: за 2022 | D3: Изменение
A4: Выручка | B4: 2218771228 | C4: 2333088493 | D4: =B4-C4 -> -114317265
A5: Себестоимость | B5: -1693087998 | C5: -1653963902 | D5: =B5-C5 -> -39124096
A6: Управленческие расходы | B6: -36107853 | C6: -35220880 | D6: =B6-C6 -> -886973
A7: Коммерческие расходы | B7: -116173283 | C7: -119940542 | D7: =B7-C7 -> 3767259
A8: Прибыль от продаж | B8: 373402094 | C8: 523963169 | D8: =B8-C8 -> -150561075
A9: Проценты к уплате | B9: 0 | C9: 0 | D9: =B9-C9 -> 0
A10: Проценты к получению | B10: 248629416 | C10: 167034022 | D10: =B10-C10 -> 81595394
A11: Доходы от участия | B11: 4053633 | C11: 2466638 | D11: =B11-C11 -> 1586995
A12: Прочие доходы | B12: 1778679761 | C12: 4468478131 | D12: =B12-C12 -> -2689798370
A13: Прочие расходы | B13: -800740586 | C13: -5061052262 | D13: =B13-C13 -> 4260311676
A14: Прибыль до налогообложения | B14: 1604024318 | C14: 100889698 | D14: =B14-C14 -> 1503134620
A15: Налог на прибыль | B15: -269647000 | C15: -40871486 | D15: =B15-C15 -> -228775514
A16: Чистая прибыль | B16: 1334377318 | C16: 60018212 | D16: =B16-C16 -> 1274359106

Sheet Потоки
A1: Потоки организации | B1: Содержание
A3: Деятельность | B3: 2023 | C3: 2022 | D3: Изменение
A4: Операционная | B4: 400724700 | C4: 541101345 | D4: =B4-C4 -> -140376645
A5: Инвестиционная | B5: -360217222 | C5: -528405848 | D5: =B5-C5 -> 168188626
A6: Финансовая | B6: -31469089 | C6: -57558191 | D6: =B6-C6 -> 26089102
A7: Чистый денежный поток | B7: =SUM(B4:B6) -> 9038389 | C7: =SUM(C4:C6) -> -44862694 | D7: =B7-C7 -> 53901083
A9: Жизненный цикл | B9: Классическая зрелость
A11: ВЫВОДЫ:
A12: Операционный поток устойчиво положительный — стабильная генерирующая способность бизнеса.
A13: Инвестиционный поток значимо отрицателен, но по модулю ниже операционного — характерно для зрелых компаний.
A14: Финансовая деятельность отрицательна — погашение обязательств и выплата дивидендов.
A15: Падение операционного потока в 2023 на 26% (-140 млрд) при росте чистой прибыли в 22 раза — сигнал о том, что прибыль растёт не за счёт операционной деятельности.

Sheet Обор
A1: Показатели оборачиваемости | C1: Содержание
A3: Средние текущие активы | B3: =AVERAGE(B4,B5) -> 2.34397e+09 | E3: 2023 год
A4: Оборотные активы на 31.12.2022 | B4: =Баланс!C19 -> 2641199991 | D4: Выручка | E4: 2218771228
A5: Оборотные активы на 31.12.2023 | B5: =Баланс!B19 -> 2.0467399e+09 | D5: Себестоимость продаж | E5: 1693087998
D6: Коммерческие расходы | E6: 116173283
A7: Средние активы (баланс) | B7: =AVERAGE(B9,B8) -> 7.4914883e+09 | D7: Управленческие расходы | E7: 36107853
A8: Активы на 31.12.2022 | B8: =Баланс!C20 -> 6676851016 | D8: Сумма | E8: =SUM(E5,E6,E7) -> 1845369134
A9: Активы на 31.12.2023 | B9: =Баланс!B20 -> 8.3061257e+09
C12: период (в днях) | D12: отрасль (2023)
A13: К1 (оборотных активов) | B13: =E4/B3 -> 0.94658688 | C13: =365/B13 -> 385.59588 | D13: 97
A14: К2 (активов) | B14: =E4/B7 -> 0.29617229 | C14: =365/B14 -> 1232.3908 | D14: 373 | E14: =365/D14 -> 0.97855228
A16: Финансовый цикл | D16: Кредиторский цикл
B17: Значения | C17: Дни | E17: Значения | F17: Дни
A18: Авансы поставщикам | B18: =AVERAGE(B19,B20) -> 6739613 | C18: =(B18/E8)*365 -> 1.3330443 | D18: Авансы покупателей | E18: =AVERAGE(E19:E20) -> 59163620 | F18: =(E18/E4)*365 -> 9.7327391
A19: Авансы поставщиком на 31.12.2022 | B19: 6995927 | D19: Авансы покупателям на 31.12.2023 | E19: 73860933
A20: Авансы поставщиком на 31.12.2023 | B20: 6483299 | D20: Авансы покупателям на 31.12.2022 | E20: 44466308
A21: Материальные запасы | B21: =AVERAGE(B22,B23) -> 73878156 | C21: =(B21/E5)*365 -> 15.926831 | D21: Устойчивые пассивы | E21: =AVERAGE(E22,E23) -> 1.8954547e+08 | F21: =(E21/E8)*365 -> 37.490654
A22: Материальные запасы на 31.12.2022 | B22: 67831061 | D22: Расчеты с бюджетом на 31.12.2022 | E22: 149277468
A23: Материальные запасы на 31.12.2023 | B23: 79925250 | D23: Расчеты с бюджетом на 31.12.2023 | E23: 229813465
A24: Незавершенное производство | B24: =AVERAGE(B25,B26) -> 11297286 | C24: =(B24/E5)*365 -> 2.4354963 | D24: Кредиторская задолженность | E24: =AVERAGE(E25,E26) -> 26365282 | F24: =(E24/E8)*365 -> 5.2148525
A25: Незавершенное производство на 31.12.2022 | B25: 8801022 | D25: КЗ на 31.12.2022 | E25: 25064417
A26: Незавершенное производство на 31.12.2023 | B26: 13793551 | D26: КЗ на 31.12.2023 | E26: 27666147
A27: Готовая продукция | B27: =AVERAGE(B29,B28) -> 28829951 | C27: =(B27/E8)*365 -> 5.7023454 | D27: Сумма | F27: =SUM(F18,F21,F24) -> 52.438245
A28: Готовая продукция на 31.12.2022 | B28: 25431978
A29: Готовая продукция на 31.12.2023 | B29: 32227924 | E29: Чистый цикл | F29: =C33-F27 -> 31.225302
A30: Дебиторская зажолженость | B30: =AVERAGE(B32,B31) -> 354187800 | C30: =(B30/E4)*365 -> 58.26583
A31: ДЗ на 31.12.2022 | B31: 338305349
A32: ДЗ на 31.12.2023 | B32: 370070251
A33: Сумма | C33: =SUM(C30,C27,C24,C21,C18) -> 83.663547

Sheet ликв
A1: Показатели ликвидности | C1: Содержание
A3: А1 | B3: =Баланс!B17 -> 117322239 | C3: > | D3: П1 | E3: 73860933
A4: А2 | B4: 278470794 | C4: > | D4: П2 | E4: =27666147+37541421 -> 65207568
A5: А3 | B5: =32227924+4060153388 -> 4092381312 | C5: > | D5: П3 | E5: 229813465
A6: А4 | B6: =8306125654-SUM(B3:B5) -> 3817951309 | C6: < | D6: П4 | E6: =8306125654 - SUM(E3:E5) -> 7937243688
A8: Тек. активы | B8: 2131856098
A9: Тек. пассивы | B9: 391256795
B11: Сургутнефтегаз: | C11: Отрасль:
A12: Коэффициент текущей ликвидности | B12: =B8/B9 -> 5.4487388 | C12: 1.05
A13: Коэффициент среднесрочной ликвидности | B13: =(B3+B4+B5)/B9 -> 11.471173 | C13: 0.04
A14: Коэффициент мнгновенной ликвидности | B14: =B3/B9 -> 0.29985994 | C14: 0.87
B16: в тыс | C16: В млрд:
A17: чок 2022 | B17: =2730653483-266497854 -> 2464155629 | C17: =B17/1000000 -> 2464.1556
A18: чок 2023 | B18: =B8-B9 -> 1740599303 | C18: =B18/1000000 -> 1740.5993
A19: изм. чок | B19: =B18-B17 -> -723556326 | C19: =B19/1000000 -> -723.55633
A20: затраты на 2023 | B20: =1693087998+116173283+36107853+269647000+B19 -> 1391459808 | C20: =B20/1000000 -> 1391.4598
A21: среднедневные платежи | B21: =B20/365 -> 3812218.7 | C21: =B21/1000000 -> 3.8122187
A22: Коэффициент покрытия | B22: =B3/B21 -> 30.775317
A24: Расчет минимально допустимого коэффициента
A25: Себестоимость+К+У | B25: =1693087998+116173283+36107853 -> 1845369134
B26: Значение
A27: Период оборота ДЗ | B27: =(B31/2218771228)*365 -> 58.26583
A28: Период оборота КЗ | B28: =(B32/B25)*365 -> 60.617023
A29: Период оборота авансов поставщикам | B29: =(B33/B25)*365 -> 1.3330443
A30: Период оборота авансов покупателей | B30: =(B34/2218771228)*365 -> 2.722072
A31: Средняя величина ДЗ | B31: =(370070251+338305349)/2 -> 354187800
A32: Средняя величина КЗ | B32: =(368881966+244053834)/2 -> 306467900
A33: Средняя величина авансов поставщикам | B33: =(6483299+6995927)/2 -> 6739613
A34: Средняя величина авансов покупателей | B34: 16547000
A35: Средняя стоимость наименее ликвидной части активов | B35: =(128911694+13793551+107757259+8801022)/2 -> 129631763
A36: Поступления от покупателей, имеющиеся к сроку погашения кредиторской задолженности и выплаты авансов поставщикам | B36: =(B31+B34)*(B28+B29)/(B27+B30) -> 3.7658364e+08
A37: Собственные средства, необход. для покрытия текущих платежей поставщикам | B37: =MAX(0,(B32+B33)-B36) -> 0
A38: Всего необходимо собственных средств (достаточный ЧОК) | B38: =B35+B37 -> 129631763
A39: Средняя фактическая величина текущих активов | B39: =(B8+4363312)/2 -> 1068109705
A40: Допустимая величина текущих пассивов | B40: =B39-B38 -> 938477942
A41: Допустимый для данного предприятия Кобл | B41: =B39/B40 -> 1.1381298

Sheet финуст
A1: Показатели финансовой устойчивости | C1: Содержание
A3: Агрегированный баланс ПАО "Сургутнефтегаз" | E3: Отчет о финансовых результатах
A4: Наименование показателя | B4: На 31 декабря 2023 года | C4: На 31 декабря 2022 года | E4: Наименование показателя | F4: за 2023
A5: Актив | E5: Выручка | F5: 2218771228
A6: 1. Внеоборотные активы | E6: Себестоимость | F6: -1693087998
A7: Нематериальные активы | B7: =258991+80199+118143995 -> 118483185 | C7: 100441138 | E7: Управленческие расходы | F7: -36107853
A8: Основные средства | B8: =1780998859-B9 -> 1683733571 | C8: 1554602062 | E8: Коммерческие расходы | F8: -116173283
A9: Незавершенные капитальные вложения | B9: 97265288 | C9: 88890783 | E9: Прибыль от продаж | F9: 373402094
A10: Долгосрочные финансовые вложения | B10: 4157418676 | C10: 2147558760 | E10: Проценты к уплате | F10: 0
A11: Прочие внеоборотные активы | B11: =68671352+48697484+85116158 -> 202484994 | C11: 144158282 | E11: Проценты к получению | F11: 248629416
A12: Итого по разделу 1 | B12: =SUM(B7:B11) -> 6259385714 | C12: =SUM(C7:C11) -> 4035651025 | E12: Доходы от участия | F12: 4053633
A13: 2. Оборотные активы | E13: Прочие доходы | F13: 1778679761
A14: Авансы поставщикам | B14: 6483299 | C14: 6995927 | E14: Прочие расходы | F14: -800740586
A15: Сырье и материалы | B15: =128911694*0.62 -> 79925250 | C15: 67831061 | E15: Прибыль до налогообложения | F15: 1604024318
A16: Незавершенное производство | B16: =128911694*0.107 -> 13793551 | C16: 8801022 | E16: Налог на прибыль | F16: -269647000
A17: Готовая продукция и товары | B17: =128911694*0.25 -> 32227924 | C17: 25431978 | E17: Чистая прибыль | F17: 1334377318
A18: Дебиторская задолженность | B18: =370070251-B14-85116158 -> 278470794 | C18: 241855930
A19: Денежные средства и денежные эквиваленты | B19: 117322239 | C19: 103639491 | E19: чок 2022 | F19: =2730653483-266497854 -> 2464155629
A20: Прочие оборотные активы | B20: =8292304+4527335+1502886150+2811094 -> 1518516883 | C20: 2186644582 | E20: чок 2023 | F20: =B16-B17 -> -18434372
A21: Итого по разделу 2 | B21: =SUM(B14:B20) -> 2.0467399e+09 | C21: =SUM(C14:C20) -> 2641199991 | E21: изм. чок | F21: =F20-F19 -> -2.48259e+09
A22: Баланс | B22: =B12+B21 -> 8.3061257e+09 | C22: =C12+C21 -> 6676851016
A23: Пассив
A24: Собственные средства
A25: Уставный капитал | B25: =43427993+192511786+317163645 -> 553103424 | C25: 540262471
A26: Накопленный капитал | B26: =6514198+6913861929 -> 6920376127 | C26: 5616029413
A27: Итого собственных средств | B27: =SUM(B25:B26) -> 7473479551 | C27: =SUM(C25:C26) -> 6156291884
A28: Заемные средства
A29: Долгосрочные обязательства | B29: 438844622 | C29: 254061278
A30: Краткосрочные обязательства
A31: Краткосрочные кредиты | B31: - | C31: -
A32: Кредиторская задолженность (счета к оплате) | B32: =368881966*0.075 -> 27666147 | C32: 25064417
A33: Авансы полученные | B33: 73860933 | C33: 44466308
A34: Расчеты с бюджетом и внебюджетными фондами | B34: =368881966*0.623 -> 2.2981346e+08 | C34: 149277468
A35: Расчеты по заработной плате | B35: - | C35: -
A36: Прочие краткосрочные обязательства | B36: =24840752+6277910+6440000-17241+21836593+524983+13253+2544686 -> 62460936 | C36: =21248154+1182725+13141+25245641 -> 47689661
A37: Итого краткосрочных обязательств | B37: =SUM(B31:B36) -> 3.9380148e+08 | C37: =SUM(C31:C36) -> 266497854
A38: Итого заемных средств | B38: =B37+B29 -> 8.326461e+08 | C38: =C37+C29 -> 520559132
A39: Баланс | B39: =SUM(B38,B27) -> 8.3061257e+09 | C39: =SUM(C38,C27) -> 6676851016
A42: Среднеотраслевой коэффициент автономии | B42: 0.2
A43: Коэффициент автономии (собственный/заемный капитал) | B43: =B27/B38 -> 8.9755774
...

Sheet рент
A1: Показатели рентабельности | C1: Содержание
A3: Агрегированный баланс ПАО "Сургутнефтегаз" | E3: Отчет о финансовых результатах
A4: Наименование показателя | B4: На 31 декабря 2023 года | C4: На 31 декабря 2022 года | E4: Наименование показателя | F4: за 2023 | G4: за 2022
A5: Актив | E5: Выручка | F5: 2218771228 | G5: 2333088493
A6: 1. Внеоборотные активы | E6: Себестоимость | F6: -1693087998 | G6: -1653963902
A7: Нематериальные активы | B7: =258991+80199+118143995 -> 118483185 | C7: 100441138 | E7: Управленческие расходы | F7: -36107853 | G7: -35220880
A8: Основные средства | B8: =1780998859-B9 -> 1683733571 | C8: 1554602062 | E8: Коммерческие расходы | F8: -116173283 | G8: -119940542
A9: Незавершенные капитальные вложения | B9: 97265288 | C9: 88890783 | E9: Прибыль от продаж | F9: 373402094 | G9: 523963169
A10: Долгосрочные финансовые вложения | B10: 4157418676 | C10: 2147558760 | E10: Проценты к уплате | F10: 0 | G10: 0
A11: Прочие внеоборотные активы | B11: =68671352+48697484+85116158 -> 202484994 | C11: 144158282 | E11: Проценты к получению | F11: 248629416 | G11: 167034022
A12: Итого по разделу 1 | B12: =SUM(B7:B11) -> 6259385714 | C12: =SUM(C7:C11) -> 4035651025 | E12: Доходы от участия | F12: 4053633 | G12: 2466638
A13: 2. Оборотные активы | E13: Прочие доходы | F13: 1778679761 | G13: 4468478131
A14: Авансы поставщикам | B14: 6483299 | C14: 6995927 | E14: Прочие расходы | F14: -800740586 | G14: -5061052262
A15: Сырье и материалы | B15: =128911694*0.62 -> 79925250 | C15: 67831061 | E15: Прибыль до налогообложения | F15: 1604024318 | G15: 100889698
A16: Незавершенное производство | B16: =128911694*0.107 -> 13793551 | C16: 8801022 | E16: Налог на прибыль | F16: -269647000 | G16: -40871486
A17: Готовая продукция и товары | B17: =128911694*0.25 -> 32227924 | C17: 25431978 | E17: Чистая прибыль | F17: 1334377318 | G17: 60018212
A18: Дебиторская задолженность | B18: =370070251-B14-85116158 -> 278470794 | C18: 241855930
A19: Денежные средства и денежные эквиваленты | B19: 117322239 | C19: 103639491
A20: Прочие оборотные активы | B20: =8292304+4527335+1502886150+2811094 -> 1518516883 | C20: 2186644582
A21: Итого по разделу 2 | B21: =SUM(B14:B20) -> 2.0467399e+09 | C21: =SUM(C14:C20) -> 2641199991
A22: Баланс | B22: =B12+B21 -> 8.3061257e+09 | C22: =C12+C21 -> 6676851016
A23: Пассив
A24: Собственные средства
A25: Уставный капитал | B25: =43427993+192511786+317163645 -> 553103424 | C25: 540262471
A26: Накопленный капитал | B26: =6514198+6913861929 -> 6920376127 | C26: 5616029413
A27: Итого собственных средств | B27: =SUM(B25:B26) -> 7473479551 | C27: =SUM(C25:C26) -> 6156291884
A28: Заемные средства
A29: Долгосрочные обязательства | B29: 438844622 | C29: 254061278
A30: Краткосрочные обязательства
A31: Краткосрочные кредиты | B31: - | C31: -
A32: Кредиторская задолженность (счета к оплате) | B32: =368881966*0.075 -> 27666147 | C32: 25064417
A33: Авансы полученные | B33: 73860933 | C33: 44466308
A34: Расчеты с бюджетом и внебюджетными фондами | B34: =368881966*0.623 -> 2.2981346e+08 | C34: 149277468
A35: Расчеты по заработной плате | B35: - | C35: -
A36: Прочие краткосрочные обязательства | B36: =24840752+6277910+6440000-17241+21836593+524983+13253+2544686 -> 62460936 | C36: =21248154+1182725+13141+25245641 -> 47689661
A37: Итого краткосрочных обязательств | B37: =SUM(B31:B36) -> 3.9380148e+08 | C37: =SUM(C31:C36) -> 266497854
A38: Итого заемных средств | B38: =B37+B29 -> 8.326461e+08 | C38: =C37+C29 -> 520559132
A39: Баланс | B39: =SUM(B38,B27) -> 8.3061257e+09 | C39: =SUM(C38,C27) -> 6676851016
B41: Сургтунефтегаз | C41: Отрасль
A42: Рентабельность собственного кап. | B42: =F17/B27 -> 0.17854833 | C42: 0.139
...

Sheet сводная
A1: Сводная таблица финансовых показателей | C1: Содержание
A3: Категория | B3: Показатель | C3: Значение | D3: Отрасль | E3: Норма / мин.доп. | F3: Оценка
A4: Ликвидность | B4: Коэффициент текущей ликвидности | C4: 5.4487388 | D4: 1.05 | E4: 1.1381298 | F4: Норма (избыток оборотных активов)
A5: Ликвидность | B5: Коэффициент абсолютной ликвидности | C5: 0.3 | D5: 0.04 | F5: Высокая
A6: Ликвидность | B6: Коэффициент среднесрочной ликвидности | C6: 11.47 | F6: Высокая
A7: Ликвидность | B7: Коэффициент покрытия среднедневных платежей (раз) | C7: 30.77 | F7: Очень высокий
A8: Фин. устойчивость | B8: Коэффициент автономии (СК/Активы) | C8: 0.9 | D8: 0.2 | E8: 0.29 | F8: Абсолютно устойчива (избыток СК)
A9: Фин. устойчивость | B9: Коэффициент финансового рычага (ЗК/СК) | C9: 0.11 | F9: Низкий — недозагрузка рычага
A10: Фин. устойчивость | B10: Коэффициент Альтмана (Z) | C10: 2.28 | E10: >2.7 | F10: Серая зона (1.81–2.7)
A11: Фин. устойчивость | B11: Коэффициент покрытия процентов | F11: Не рассчитывается (нет % к уплате)
A12: Фин. устойчивость | B12: Коэффициент ОДАСС | C12: 1.26 | D12: 0.07 | E12: >1 | F12: Инвест.политика соответствует возможностям
A13: Рентабельность | B13: ROE (Чистая прибыль / СК) | C13: 0.1785 | D13: 0.139 | F13: Выше отрасли
A14: Рентабельность | B14: ROA (Чистая прибыль / Активы) | C14: 0.1606 | D14: 0.064 | F14: Значительно выше отрасли
A15: Рентабельность | B15: Операционная маржа (ROS, по операционной прибыли) | C15: =рент!B47 -> 0.12621922 | D15: 0.128 | F15: Существенно ниже чистого ROS — операционная маржа невысокая
A16: Рентабельность | B16: Рентабельность продаж (ROS, по чистой прибыли) | C16: 0.601 | D16: 0.127 | F16: Завышена прочими доходами (валютная переоценка)
A17: Оборачиваемость | B17: Период оборота активов (дн) | C17: =Обор!C14 -> 1232.3908 | D17: 373 | F17: Медленнее отрасли в 4 раза
A18: Оборачиваемость | B18: Период оборота текущих активов (дн) | C18: =Обор!C13 -> 385.59588 | D18: 97 | F18: Медленнее отрасли в 4 раза
A19: Оборачиваемость | B19: Период оборота запасов (дн) | C19: 16 | D19: 8 | F19: Медленнее - нужна оптимизация управления запасами
A20: Оборачиваемость | B20: Период оборота ДЗ (дн) | C20: 58 | D20: 51 | F20: Медленнее
A21: Оборачиваемость | B21: Период оборота КЗ (дн, общая) | C21: 61 | F21: Нейтрально
A22: Оборачиваемость | B22: Производственно-коммерческий цикл (дн) | C22: 84 | F22: Норма
A23: Оборачиваемость | B23: Чистый цикл (дн) | C23: 31 | F23: Норма для отрасли
A24: Прибыльность | B24: Маржинальная прибыль (млрд ₽) | C24: 1744 | F24: Положительная
A25: Прибыльность | B25: Производственный рычаг | C25: 4.67 | F25: Чувствительность к изменению выручки
A26: Прибыльность | B26: Запас прочности | C26: 0.214 | F26: Зона низкого риска
A27: Экон. прибыль | B27: Стоимость капитала (Ke) | C27: 0.2337
A28: Экон. прибыль | B28: Экономическая прибыль (EVA), млрд ₽ | C28: -412 | E28: >0 | F28: Бизнес разрушает стоимость — главный риск

Sheet эк.приб.
A1: Экономическая прибыль | B1: =(B3-B4)*B2 -> -4.1206213e+08 | C1: компания разрушает стоимость
A2: Е | B2: =7473479551 -> 7473479551 | C2: Собственный капитал (СК), тыс. ₽
A3: ROE | B3: =ОФР!B16/(B2) -> 0.17854833 | C3: Рентабельность собств. Капитала
A4: Ke | B4: =(B5+B6*B8) -> 0.23368492 | C4: Стоимость собств. Капитала
A5: Rf | B5: 0.1186 | C5: Безрисковая ставка
A6: B lev | B6: =B7*(1+(1-0.25)*Баланс!B36/Баланс!B25) -> 1.0293821 | C6: Бета levered
A7: Bu | B7: 0.95 | C7: Бета unlevered — отраслевая (нефтегаз)
A8: (Rm-Rf) | B8: 0.1118 | C8: Премия за рыночный риск (Equity Risk Premium, Damodaran для развивающихся рынков)
A10: Вывод
A11: ROE (17.85%) ниже стоимости капитала Ke (23.37%) — отрицательная эк. прибыль означает, что
A12: компания не покрывает требуемую доходность инвесторов. С точки зрения экономической
A13: эффективности бизнес не создаёт стоимость для акционеров, а наоборот — разрушает её.
A14: Это главный риск компании несмотря на формально высокую чистую рентабельность.
A16: Методология
A17: 1. CAPM: Ke = Rf + B·(Rm - Rf) — стандартная модель ценообразования капитальных активов
A18: 2. Beta levered: B = Bu·(1 + (1-t)·D/E) — корректирует unlevered бету на долговую нагрузку
A19: 3. Эк. прибыль = (ROE - Ke) · СК — отражает создание/разрушение стоимости относительно стоимости капитала
A20: 4. У Сургутнефтегаза D/E ≈ 0.11 (низкий долг) — поэтому Beta levered близка к Bu
A22: Источники
A23: ЦБ РФ
A24: Damodaran (нефтегаз), Emerging Markets
